<?xml version='1.0' encoding='utf-8'?>
<robot xmlns:xacro="http://www.ros.org/wiki/xacro" name="panda">
  <xacro:macro name="panda_arm" params="arm_id:='panda' description_pkg:='franka_description' connected_to:='' xyz:='0 0 0' rpy:='0 0 0' hw_interface:='PositionJointInterface'">
    <xacro:unless value="${not connected_to}">
      <joint name="${arm_id}_joint_${connected_to}" type="fixed">
        <parent link="${connected_to}"/>
        <child link="${arm_id}_link0"/>
        <origin rpy="${rpy}" xyz="${xyz}"/>
      </joint>
    </xacro:unless>

    <link name="${arm_id}_link0">
      <visual>
        <geometry>
          <mesh filename="package://${description_pkg}/meshes/visual/link0.dae.dae"/>
        </geometry>
      </visual>
      <collision>
        <geometry>
          <mesh filename="package://${description_pkg}/meshes/collision/link0.stl"/>
        </geometry>
      </collision>
      <inertial>
        <!-- ATTENTION! Copied from another robot! Needs to be defined correctly! -->
        <mass value="1.2" />
        <origin rpy="0 0 0" xyz="0 0 0.055" />
        <inertia ixx="0.00229" ixy="0" ixz="0" iyy="0.00216" iyz="0" izz="0.00229" />
      </inertial>
    </link>
    <gazebo reference="${arm_id}_link0">
      <kd>1.0</kd>
      <mu1>0.8</mu1>
      <mu2>0.8</mu2>
      <maxVel>0.0</maxVel>
      <minDepth>0.001</minDepth>
    </gazebo>

    <link name="${arm_id}_link1">
      <visual>
        <geometry>
          <mesh filename="package://${description_pkg}/meshes/visual/link1.dae.dae"/>
        </geometry>
      </visual>
      <collision>
        <geometry>
          <mesh filename="package://${description_pkg}/meshes/collision/link1.stl"/>
        </geometry>
      </collision>
      <inertial>
        <!-- ATTENTION! Copied from another robot! Needs to be defined correctly! -->
        <mass value="2.0" />
        <origin rpy="0 0 0" xyz="0 0 -0.130" />
        <inertia ixx="0.0136666666667" ixy="0" ixz="0" iyy="0.0118666666667" iyz="0" izz="0.003" />
      </inertial>
    </link>
    <gazebo reference="${arm_id}_link1">
      <kd>1.0</kd>
      <mu1>0.8</mu1>
      <mu2>0.8</mu2>
      <maxVel>0.0</maxVel>
      <minDepth>0.001</minDepth>
    </gazebo>

    <joint name="${arm_id}_joint1" type="revolute">
      <safety_controller k_position="100.0" k_velocity="40.0" soft_lower_limit="-2.8973" soft_upper_limit="2.8973"/>
      <origin rpy="0 0 0" xyz="0 0 0.333"/>
      <parent link="${arm_id}_link0"/>
      <child link="${arm_id}_link1"/>
      <axis xyz="0 0 1"/>
      <limit effort="87" lower="-2.8973" upper="2.8973" velocity="2.1750"/>
      <dynamics damping="0.5" friction="1.0"/>
    </joint>
    <transmission name="${arm_id}_transmission1">
      <type>transmission_interface/SimpleTransmission</type>
      <joint name="${arm_id}_joint1">
	    <hardwareInterface>hardware_interface/${hw_interface}</hardwareInterface>
      </joint>
      <actuator name="${arm_id}_motor1">
	    <hardwareInterface>hardware_interface/${hw_interface}</hardwareInterface>
	    <mechanicalReduction>1</mechanicalReduction>
      </actuator>
    </transmission>

    <link name="${arm_id}_link2">
      <visual>
        <geometry>
          <mesh filename="package://${description_pkg}/meshes/visual/link2.dae.dae"/>
        </geometry>
      </visual>
      <collision>
        <geometry>
          <mesh filename="package://${description_pkg}/meshes/collision/link2.stl"/>
        </geometry>
      </collision>
      <inertial>
        <!-- ATTENTION! Copied from another robot! Needs to be defined correctly! -->
        <mass value="2.0" />
        <origin rpy="0 0 0" xyz="0 -0.05 0.04" />
        <inertia ixx="0.0136666666667" ixy="0" ixz="0" iyy="0.0118666666667" iyz="0" izz="0.003" />
      </inertial>
    </link>
    <gazebo reference="${arm_id}_link2">
      <kd>1.0</kd>
      <mu1>0.8</mu1>
      <mu2>0.8</mu2>
      <maxVel>0.0</maxVel>
      <minDepth>0.001</minDepth>
    </gazebo>

    <joint name="${arm_id}_joint2" type="revolute">
      <safety_controller k_position="100.0" k_velocity="40.0" soft_lower_limit="-1.7628" soft_upper_limit="1.7628"/>
      <origin rpy="${-pi/2} 0 0" xyz="0 0 0"/>
      <parent link="${arm_id}_link1"/>
      <child link="${arm_id}_link2"/>
      <axis xyz="0 0 1"/>
      <limit effort="87" lower="-1.7628" upper="1.7628" velocity="2.1750"/>
      <dynamics damping="0.5" friction="1.0"/>
    </joint>
    <transmission name="${arm_id}_transmission2">
      <type>transmission_interface/SimpleTransmission</type>
      <joint name="${arm_id}_joint2">
	    <hardwareInterface>hardware_interface/${hw_interface}</hardwareInterface>
      </joint>
      <actuator name="${arm_id}_motor2">
	    <hardwareInterface>hardware_interface/${hw_interface}</hardwareInterface>
	    <mechanicalReduction>1</mechanicalReduction>
      </actuator>
    </transmission>

    <link name="${arm_id}_link3">
      <visual>
        <geometry>
          <mesh filename="package://${description_pkg}/meshes/visual/link3.dae.dae"/>
        </geometry>
      </visual>
      <collision>
        <geometry>
          <mesh filename="package://${description_pkg}/meshes/collision/link3.stl"/>
        </geometry>
      </collision>
      <inertial>
        <!-- ATTENTION! Copied from another robot! Needs to be defined correctly! -->
        <mass value="2.0" />
        <origin rpy="0 0 0" xyz="0 0.0 0.0" />
        <inertia ixx="0.011" ixy="0" ixz="0" iyy="0.0118666666667" iyz="0" izz="0.003" />
      </inertial>
    </link>
    <gazebo reference="${arm_id}_link3">
      <kd>1.0</kd>
      <mu1>0.8</mu1>
      <mu2>0.8</mu2>
      <maxVel>0.0</maxVel>
      <minDepth>0.001</minDepth>
    </gazebo>

    <joint name="${arm_id}_joint3" type="fixed">
      <origin rpy="${pi/2} 0 0" xyz="0 -0.316 0"/>
      <parent link="${arm_id}_link2"/>
      <child link="${arm_id}_link3"/>
      <axis xyz="0 0 1"/>
    </joint>

    <link name="${arm_id}_link4">
      <visual>
        <geometry>
          <mesh filename="package://${description_pkg}/meshes/visual/link4.dae.dae"/>
        </geometry>
      </visual>
      <collision>
        <geometry>
          <mesh filename="package://${description_pkg}/meshes/collision/link4.stl"/>
        </geometry>
      </collision>
      <inertial>
        <!-- ATTENTION! Copied from another robot! Needs to be defined correctly! -->
        <mass value="2.0" />
        <origin rpy="0 0 0" xyz="-0.04 0.06 0.0" />
        <inertia ixx="0.01" ixy="0" ixz="0" iyy="0.011" iyz="0" izz="0.0129" />
      </inertial>
    </link>
    <gazebo reference="${arm_id}_link4">
      <kd>1.0</kd>
      <mu1>0.8</mu1>
      <mu2>0.8</mu2>
      <maxVel>0.0</maxVel>
      <minDepth>0.001</minDepth>
    </gazebo>

    <joint name="${arm_id}_joint4" type="revolute">
      <safety_controller k_position="100.0" k_velocity="40.0" soft_lower_limit="-3.0718" soft_upper_limit="-0.0698"/>
      <origin rpy="${pi/2} 0 0" xyz="0.0825 0 0"/>
      <parent link="${arm_id}_link3"/>
      <child link="${arm_id}_link4"/>
      <axis xyz="0 0 1"/>
      <limit effort="87" lower="-3.0718" upper="-0.0698" velocity="2.1750"/>
      <dynamics damping="0.5" friction="1.0"/>
    </joint>
    <transmission name="${arm_id}_transmission4">
      <type>transmission_interface/SimpleTransmission</type>
      <joint name="${arm_id}_joint4">
	    <hardwareInterface>hardware_interface/${hw_interface}</hardwareInterface>
      </joint>
      <actuator name="${arm_id}_motor4">
	    <hardwareInterface>hardware_interface/${hw_interface}</hardwareInterface>
	    <mechanicalReduction>1</mechanicalReduction>
      </actuator>
    </transmission>

    <link name="${arm_id}_link5">
      <visual>
        <geometry>
          <mesh filename="package://${description_pkg}/meshes/visual/link5.dae.dae"/>
        </geometry>
      </visual>
      <collision>
        <geometry>
          <mesh filename="package://${description_pkg}/meshes/collision/link5.stl"/>
        </geometry>
      </collision>
      <inertial>
        <!-- ATTENTION! Copied from another robot! Needs to be defined correctly! -->
        <mass value="2.0" />
        <origin rpy="0 0 0" xyz="0 0.03 -0.123" />
        <inertia ixx="0.0126506666667" ixy="0" ixz="0" iyy="0.0108506666667" iyz="0" izz="0.003" />
      </inertial>
    </link>
    <gazebo reference="${arm_id}_link5">
      <kd>1.0</kd>
      <mu1>0.8</mu1>
      <mu2>0.8</mu2>
      <maxVel>0.0</maxVel>
      <minDepth>0.001</minDepth>
    </gazebo>

    <joint name="${arm_id}_joint5" type="revolute">
      <safety_controller k_position="100.0" k_velocity="40.0" soft_lower_limit="-2.8973" soft_upper_limit="2.8973"/>
      <origin rpy="${-pi/2} 0 0" xyz="-0.0825 0.384 0"/>
      <parent link="${arm_id}_link4"/>
      <child link="${arm_id}_link5"/>
      <axis xyz="0 0 1"/>
      <limit effort="12" lower="-2.8973" upper="2.8973" velocity="2.6100"/>
      <dynamics damping="0.5" friction="1.0"/>
    </joint>
    <transmission name="${arm_id}_transmission5">
      <type>transmission_interface/SimpleTransmission</type>
      <joint name="${arm_id}_joint5">
	    <hardwareInterface>hardware_interface/${hw_interface}</hardwareInterface>
      </joint>
      <actuator name="${arm_id}_motor5">
	    <hardwareInterface>hardware_interface/${hw_interface}</hardwareInterface>
	    <mechanicalReduction>1</mechanicalReduction>
      </actuator>
    </transmission>

    <link name="${arm_id}_link6">
      <visual>
        <geometry>
          <mesh filename="package://${description_pkg}/meshes/visual/link6.dae.dae"/>
        </geometry>
      </visual>
      <collision>
        <geometry>
          <mesh filename="package://${description_pkg}/meshes/collision/link6.stl"/>
        </geometry>
      </collision>
      <inertial>
        <!-- ATTENTION! Copied from another robot! Needs to be defined correctly! -->
        <mass value="1.5" />
        <origin rpy="0 0 0" xyz="0.05 0 0.0" />
        <inertia ixx="0.002" ixy="0" ixz="0" iyy="0.00260416666667" iyz="0" izz="0.00260416666667" />
      </inertial>
    </link>
    <gazebo reference="${arm_id}_link6">
      <kd>1.0</kd>
      <mu1>0.8</mu1>
      <mu2>0.8</mu2>
      <maxVel>0.0</maxVel>
      <minDepth>0.001</minDepth>
    </gazebo>

    <joint name="${arm_id}_joint6" type="fixed">
      <origin rpy="${pi/2} 0 0" xyz="0 0 0"/>
      <parent link="${arm_id}_link5"/>
      <child link="${arm_id}_link6"/>
      <axis xyz="0 0 1"/>
    </joint>

    <link name="${arm_id}_link7">
      <visual>
        <geometry>
          <mesh filename="package://${description_pkg}/meshes/visual/link7.dae.dae"/>
        </geometry>
      </visual>
      <collision>
        <geometry>
          <mesh filename="package://${description_pkg}/meshes/collision/link7.stl"/>
        </geometry>
      </collision>
      <inertial>
        <!-- ATTENTION! Copied from another robot! Needs to be defined correctly! -->
        <mass value="0.8" />
        <origin xyz="0 0 0" />
        <inertia ixx="6.66666666667e-05" ixy="0" ixz="0" iyy="6.66666666667e-05" iyz="0" izz="0.00012" />
      </inertial>
    </link>
    <gazebo reference="${arm_id}_link7">
      <kd>1.0</kd>
      <mu1>0.8</mu1>
      <mu2>0.8</mu2>
      <maxVel>0.0</maxVel>
      <minDepth>0.001</minDepth>
    </gazebo>

    <joint name="${arm_id}_joint7" type="fixed">
      <origin rpy="${pi/2} 0 0" xyz="0.088 0 0"/>
      <parent link="${arm_id}_link6"/>
      <child link="${arm_id}_link7"/>
      <axis xyz="0 0 1"/>
    </joint>

    <link name="${arm_id}_link8"/>
    <joint name="${arm_id}_joint8" type="fixed">
      <origin rpy="0 0 0" xyz="0 0 0.107"/>
      <parent link="${arm_id}_link7"/>
      <child link="${arm_id}_link8"/>
      <axis xyz="0 0 0"/>
    </joint>
  </xacro:macro>
</robot>
